Workbook

Sheet 华腾2021
A1: 序号 | B1: 工程地点及内容 | C1: 单位名称 | D1: 签订日期 | E1: 合同额 | F1: 结算值 | G1: 已付款 | H1: 欠付款 | I1: 备注
A2: 21-HT-YY-OD-001 | B2: 三东小区冬季抢修 | C2: 天津天铖力帆建筑工程有限公司 | D2: 2021.4.1 | E2: 25864 | F2: 25864 | G2: 25864 | H2: =F2-G2 -> 0 | I2: 齐
A3: 21-HT-YY-OD-002 | B3: 和平村站内检修 | C3: 天津永强东成市政工程有限公司 | E3: 87020 | F3: 87020 | G3: =47020+40000 -> 87020 | H3: =F3-G3 -> 0 | I3: 齐
A4: 21-HT-YY-OD-003 | B4: 东城家园冬季检修 | C4: 天津永强东成市政工程有限公司 | E4: 46176 | F4: 46176 | G4: 46176 | H4: =F4-G4 -> 0 | I4: 齐
A5: 21-HT-YY-OD-004 | B5: 冬季内网抢修 | C5: 禹王（北京）科技工程有限公司 | D5: 2021.4.1 | E5: 255735 | F5: 255735 | G5: =45735+50000+50000+110000 -> 255735 | H5: =F5-G5 -> 0 | I5: 齐
A6: 21-HT-YY-OD-005 | B6: 百合春天 九号站冬季抢修 | C6: 天津恒鼎建筑工程有限公司 | D6: 2020.9.9 | E6: 361256 | F6: 361256 | G6: =41256+50000+40000+50000+80000+100000 -> 361256 | H6: =F6-G6 -> 0 | I6: 齐
A7: 21-HT-YY-OD-006 | B7: 万新供热2020-2021冬季运行供热管网抢修 | C7: 河北省广平县建筑安装企业集团公司 | E7: 136139 | F7: 136139 | G7: =46139+90000 -> 136139 | H7: =F7-G7 -> 0 | I7: 齐
A8: 21-HT-YY-OD-007 | B8: 海河华馨冬季抢修 | C8: 天津市信恒建筑工程有限公司 | D8: 2020.10.20 | E8: 196770 | F8: 196770 | G8: =46770+50000+80000+20000 -> 196770 | H8: =F8-G8 -> 0 | I8: 齐
A9: 21-HT-YY-OD-008 | B9: 团结北里秋丽家园冬季抢修 | C9: 天津军星管业集团建设工程有限公司 | E9: 29070 | F9: 29070 | G9: 29070 | H9: =F9-G9 -> 0 | I9: 齐
A10: 21-HT-YY-OD-009 | B10: 嘉华翠海朱庄子一村冬季抢修 | C10: 隽融建工（集团）有限公司 | E10: 90133 | F10: 90133 | G10: =45066+45067 -> 90133 | H10: =F10-G10 -> 0 | I10: 齐
A11: 21-HT-YY-OD-010 | B11: 6号站万新公寓冬季抢修 | C11: 天津市翔凯建筑安装工程有限公司 | E11: 55095 | F11: 55095 | G11: 55095 | H11: =F11-G11 -> 0 | I11: 齐
A12: 21-HT-YY-001 | B12: 2021年万新村1#2#3#换热站屋顶修缮工程 | C12: 天津大鼎市政工程有限公司 | D12: 2021.7.09 | E12: 179970 | F12: 172346 | G12: 172346 | H12: =F12-G12 -> 0 | I12: 齐
A13: 21-HT-YY-002 | B13: 2021年万新村7#8#9#换热站屋顶修缮工程 | C13: 天津大鼎市政工程有限公司 | D13: 2021.7.09 | E13: 167424 | F13: 160232 | G13: 160232 | H13: =F13-G13 -> 0 | I13: 齐
A14: 21-HT-YY-003 | B14: 2021年倚虹里1#-5#楼管道保温修缮工程 | C14: 天津大鼎市政工程有限公司 | D14: 2021.7.09 | E14: 163218 | F14: 161004 | G14: 161004 | H14: =F14-G14 -> 0 | I14: 齐
A15: 21-HT-YY-004 | B15: 2021年松风西里1#-6#楼管道保温修缮工程 | C15: 天津大鼎市政工程有限公司 | D15: 2021.7.09 | E15: 184255 | F15: 177994 | G15: =48994+49000+80000 -> 177994 | H15: =F15-G15 -> 0 | I15: 齐
A16: 21-HT-YY-005 | B16: 2021年一村换热站屋顶修缮工程 | C16: 天津大鼎市政工程有限公司 | D16: 2021.7.09 | E16: 161021 | F16: 153831 | G16: =46149+107682 -> 153831 | H16: =F16-G16 -> 0 | I16: 齐
A17: 21-HT-YY-006 | B17: 2021年和平村锅炉房手动葫芦改造工程 | C17: 天津大鼎市政工程有限公司 | D17: 2021.7.14 | E17: 124818 | F17: 115036 | G17: =45036+35000+35000 -> 115036 | H17: =F17-G17 -> 0 | I17: 齐
A18: 21-HT-YY-007 | B18: 2021年倚虹中里1#-8#楼管道保温修缮工程 | C18: 天津大鼎市政工程有限公司 | D18: 2021.7.09 | E18: 173010 | F18: 169972 | G18: =48972+121000 -> 169972 | H18: =F18-G18 -> 0 | I18: 齐
A19: 21-HT-YY-008 | B19: 2021年倚虹东里1#-5#楼管道保温修缮工程 | C19: 天津大鼎市政工程有限公司 | D19: 2021.7.09 | E19: 159886 | F19: 158558 | G19: =48558+45000+65000 -> 158558 | H19: =F19-G19 -> 0 | I19: 齐
A20: 21-HT-YY-009 | B20: 2021年万新村锅炉手动葫芦改造工程 | C20: 天津大鼎市政工程有限公司 | D20: 2021.7.14 | E20: 110949 | F20: 102255 | G20: =30676+41579+30000 -> 102255 | H20: =F20-G20 -> 0 | I20: 齐
A21: 21-HT-YY-010 | B21: 2021年松风东里1#-5#楼管道保温修缮工程 | C21: 天津大鼎市政工程有限公司 | D21: 2021.7.09 | E21: 167423 | F21: 160729 | G21: =48000+42729+70000 -> 160729 | H21: =F21-G21 -> 0 | I21: 齐
A22: 21-HT-YY-011 | B22: 2021年香兰家园换热站屋顶修缮工程 | C22: 天津大鼎市政工程有限公司 | D22: 2021.7.09 | E22: 174126 | F22: 166648 | G22: =46648+120000 -> 166648 | H22: =F22-G22 -> 0 | I22: 齐
A23: 21-HT-YY-012 | B23: 2021年百合春天换热站屋顶修缮工程 | C23: 天津大鼎市政工程有限公司 | D23: 2021.7.09 | E23: 182801 | F23: 175177 | G23: =45177+130000 -> 175177 | H23: =F23-G23 -> 0 | I23: 齐
A24: 21-HT-YY-013 | B24: 2021年沧浪西里1#2#3#入口截门更换工程 | C24: 中舰建筑工程（天津）有限公司 | D24: 2021.7.09 | E24: 116242 | F24: 108621 | G24: 108621 | H24: =F24-G24 -> 0 | I24: 齐
A25: 21-HT-YY-014 | B25: 2021年冠云中里18#-22#入口截门更换工程 | C25: 中舰建筑工程（天津）有限公司 | D25: 2021.7.09 | E25: 165605 | F25: 154987 | G25: =46496+48491+30000+30000 -> 154987 | H25: =F25-G25 -> 0 | I25: 齐
A26: 21-HT-YY-015 | B26: 2021年环秀东里19#20#21#22#入口截门更换工程 | C26: 中舰建筑工程（天津）有限公司 | D26: 2021.7.09 | E26: 149885 | F26: 140957 | G26: =42287+48670+50000 -> 140957 | H26: =F26-G26 -> 0 | I26: 齐
A27: 21-HT-YY-016 | B27: 2021年环秀西里1#2#3#4#5#入口截门更换工程 | C27: 中舰建筑工程（天津）有限公司 | D27: 2021.7.09 | E27: 150538 | F27: 140318 | G27: 140318 | H27: =F27-G27 -> 0 | I27: 齐
A28: 21-HT-YY-017 | B28: 2021年曲溪东里1#2#3#4#5#入口截门更换工程 | C28: 中舰建筑工程（天津）有限公司 | D28: 2021.7.09 | E28: 163780 | F28: 153733 | G28: =46119+47614+60000 -> 153733 | H28: =F28-G28 -> 0 | I28: 齐
A29: 21-HT-YY-018 | B29: 2021年天泉东里3#4#入口截门更换工程 | C29: 中舰建筑工程（天津）有限公司 | D29: 2021.7.09 | E29: 151117 | F29: 141768 | G29: 141768 | H29: =F29-G29 -> 0 | I29: 齐
A30: 21-HT-YY-019 | B30: 2021年秀悦换热站变压器维修项目 | C30: 中舰建筑工程（天津）有限公司 | D30: 2021.7.14 | E30: 188800 | G30: =48800+140000 -> 188800 | H30: =E30-G30 -> 0
A31: 21-HT-YY-020 | B31: 2021年天泉西里14#15#16#17#入口截门更换工程 | C31: 中舰建筑工程（天津）有限公司 | D31: 2021.7.09 | E31: 181657 | F31: 169831 | G31: 169831 | H31: =F31-G31 -> 0 | I31: 齐
A32: 21-HT-YY-021 | B32: 2021年远翠东里15#-23#入口截门更换工程 | C32: 中舰建筑工程（天津）有限公司 | D32: 2021.7.09 | E32: 190750 | F32: 177941 | G32: 177941 | H32: =F32-G32 -> 0 | I32: 齐
A33: 21-HT-YY-022 | B33: 2021年和平村供热站变压器维修项目 | C33: 中舰建筑工程（天津）有限公司 | D33: 2021.7.14 | E33: 152701 | G33: =45810+46891+60000 -> 152701 | H33: =E33-G33 -> 0 | I33: 齐
A34: 21-HT-YY-023 | B34: 2021年贵环换热站变压器维修项目 | C34: 中舰建筑工程（天津）有限公司 | D34: 2021.7.14 | E34: 133848 | G34: =40154+43694+50000 -> 133848 | H34: =E34-G34 -> 0 | I34: 找财务要了复印件
A35: 21-HT-YY-024 | B35: 2021年香兰嘉园换热站变压器维修项目 | C35: 中舰建筑工程（天津）有限公司 | D35: 2021.7.14 | E35: 136749 | G35: =46749+48000+42000 -> 136749 | H35: =E35-G35 -> 0 | I35: 齐
A36: 21-HT-YY-025 | B36: 2021华馨地热站变压器维修项目 | C36: 中舰建筑工程（天津）有限公司 | D36: 2021.7.14 | E36: 192817 | G36: =46000+46817+100000 -> 192817 | H36: =E36-G36 -> 0 | I36: 齐
A37: 21-HT-YY-026 | B37: 2021年东城家园及和平村夏季检修工程 | C37: 天津永强东成市政工程有限公司 | D37: 2021.7.22 | E37: 170458 | F37: 170458 | G37: =40458+44771+85229 -> 170458 | H37: =E37-G37 -> 0 | I37: 齐
A38: 21-HT-YY-027 | B38: 华腾招标代理咨询费/华腾供热站入围项目邀请招标 | C38: 天津津建工程造价咨询有限公司 | D38: 2021.7.02 | E38: 1291000 | G38: =45000+45000+45000+59000+150000+50000+150000+50000+100000 -> 694000 | H38: =E38-G38 -> 597000 | I38: 付款单据齐
A39: 21-HT-YY-028 | B39: 华腾供热有限责任公司各换热站变速器检测校准项目 | C39: 天津天星科技发展有限公司 | E39: 194400 | G39: =49400+45000+100000 -> 194400 | H39: =E39-G39 -> 0 | I39: 齐
A40: 21-HT-YY-029 | B40: 华腾供热有限责任公司流量计维护保养项目 | C40: 中舰建筑工程（天津）有限公司 | E40: 198856 | G40: =48856+48000+102000 -> 198856 | H40: =E40-G40 -> 0 | I40: 齐
...

Sheet 华腾2022
A1: 序号 | B1: 工程地点及内容 | C1: 单位名称 | D1: 签订日期 | E1: 合同额 | F1: 结算值 | G1: 已付款 | H1: 欠付款 | I1: 备注
A2: 22-HT-YY-001 | B2: 华腾供热站换热站变速器检测维修项目 | C2: 天津市昌青建筑工程有限公司 | D2: 2022.6.18 | E2: 194400 | G2: =100000+94400 -> 194400 | H2: =E2-G2 -> 0
A3: 22-HT-YY-002 | B3: 万新村1-7、9号换热站、万新公寓换热站、舒畅欣园换热站等板式换热器清洗维修 | C3: 中舰建筑工程（天津）有限公司 | D3: 2022.6.18 | E3: 101585 | G3: 101585 | H3: =E3-G3 -> 0
A4: 22-HT-YY-003 | B4: 东瑞地热站热泵机组维修保养项目 | C4: 天津市昌青建筑工程有限公司 | D4: 2022.6.13 | E4: 197320 | G4: 197320 | H4: =E4-G4 -> 0
A5: 22-HT-YY-004 | B5: 东惠地热站热泵机组维修保养项目 | C5: 天津大展建筑工程有限公司 | D5: 2022.6.13 | E5: 194815 | G5: =44815+150000 -> 194815 | H5: =E5-G5 -> 0
A6: 22-HT-YY-005 | B6: 华腾供热站流量计维护保养项目 | C6: 天津市昌青建筑工程有限公司 | D6: 2022.7.1 | E6: 198845 | G6: =100000+98845 -> 198845 | H6: =E6-G6 -> 0
A7: 22-HT-YY-006 | B7: 华腾供热站各换热站电磁阀维修保养项目 | C7: 天津大展建筑工程有限公司 | D7: 2022.6.24 | E7: 143000 | G7: =43000+100000 -> 143000 | H7: =E7-G7 -> 0
A8: 22-HT-YY-007 | B8: 万新村站（六号站、昆仑里、临月里、警苑、三石化）热量表维修 | C8: 天津久弘建筑工程有限公司 | D8: 2022.6.24 | E8: 65000 | G8: 65000 | H8: =E8-G8 -> 0
A9: 22-HT-YY-008 | B9: 华腾供热水泵维修 | C9: 天津市北辰区大力机械设备维修中心 | E9: 167500 | G9: =30000+90000+47500 -> 167500 | H9: =E9-G9 -> 0
A10: 22-HT-YY-009 | B10: 华腾供热水泵采购 | C10: 天津市红桥区丰顺盈机电设备销售中心 | E10: 65400 | G10: 65400 | H10: =E10-G10 -> 0
A11: 22-HT-YY-010 | B11: 品香苑地热站热泵机组维修保养 | C11: 正弘建业（天津）建设发展有限公司 | D11: 2022.7.8 | E11: 178740 | G11: =48740+130000 -> 178740 | H11: =E11-G11 -> 0
A12: 22-HT-YY-011 | B12: 秀悦园地热站热泵机组维修保养 | C12: 天津大鼎市政工程有限公司 | D12: 2022.6.24 | E12: 199300 | G12: 199300 | H12: =E12-G12 -> 0
A13: 22-HT-YY-012 | B13: 华馨地热站热泵机组维修 | C13: 中建贺庆（天津）建设有限公司 | D13: 2022.7.1 | E13: 155800 | G13: =45800+110000 -> 155800 | H13: =E13-G13 -> 0
A14: 22-HT-YY-013 | B14: 海河新天地地热站热泵机组维修 | C14: 中舰建筑工程（天津）有限公司 | E14: 194485 | G14: =100000+94485 -> 194485 | H14: =E14-G14 -> 0 | I14: 无合同
A15: 22-HT-YY-014 | B15: 华腾供热站水泵维修 | C15: 天津市北辰区大力机械设备维修中心 | D15: 2022.7.28 | E15: 157110 | G15: =80000+77110 -> 157110 | H15: =E15-G15 -> 0
A16: 22-HT-YY-015 | B16: 华腾供热给水工程 | C16: 天津市华源自来水工程有限公司 | D16: 2022.9.13 | E16: 192420 | G16: 192420 | H16: =E16-G16 -> 0
A17: 22-HT-YY-016 | B17: 和平村锅炉房燃气锅炉内部清垢喷防腐涂料维修保养 | C17: 天津久弘建筑工程有限公司 | E17: 70200 | G17: 70200 | H17: =E17-G17 -> 0 | I17: 无合同
A18: 22-HT-YY-017 | B18: 万新村村锅炉房燃气锅炉内部清垢喷防腐涂料维修保养 | C18: 天津云泽建筑工程有限公司 | D18: 2022.9.14 | E18: 190000 | G18: =90000+100000 -> 190000 | H18: =E18-G18 -> 0
A19: 22-HT-YY-018 | B19: 华腾供热站锅炉间改造自控系统 | C19: 天津市优硕科技有限公司 | D19: 2022.6.30 | E19: 123760 | H19: =E19-G19 -> 123760
A20: 22-HT-YY-019 | B20: 华腾供热站趸热换热间改造自控系统 | C20: 天津市擎诚科技有限公司 | D20: 2022.9.15 | E20: 194800 | H20: 194800
A21: 22-HT-YY-020 | B21: 2022-2023华腾供热冬季保驾 | C21: 天津市津东创展城市发展有限公司 | E21: =5147900.1 -> 5147900.1 | G21: =2274180.05+2873720.05 -> 5147900.1 | H21: =E21-G21 -> 0
A22: 22-HT-YY-021 | B22: 更换东康2台45kw屏蔽泵，四台季景排污泵及配套电箱 | C22: 天津市北辰区大力机械设备维修中心 | E22: 155900 | G22: 155900 | H22: =E22-G22 -> 0
A23: 22-HT-YY-022 | B23: 品香、香兰地热站提井施工 | C23: 天津海河新能源集团有限公司 | D23: 2022.10.20 | E23: 177661.28 | G23: =50000+50000+50000 -> 150000 | H23: =E23-G23 -> 27661.28
A24: 22-HT-YY-023 | C24: 取消
A25: 22-HT-YY-024 | B25: 和平村供热站彩色触摸屏采购 | C25: 天津市北方建华机电设备有限公司 | E25: 83200 | G25: 83200 | H25: =E25-G25 -> 0
A26: 22-HT-YY-025 | B26: 天津市华腾供热有限责任公司在线监测运维工作 | C26: 天津市天一生态环境科技有限公司 | D26: 2022.10.22 | E26: 360500 | G26: =100000+100000 -> 200000 | H26: =E26-G26 -> 160500
A27: 22-HT-YY-026 | B27: 华腾供热造价咨询合同 | C27: 天津市嘉华房地产开发有限责任公司 | D27: 2022.3.29 | E27: 无明细 | H27: 无明细
A28: 22-HT-YY-027 | B28: 万新村锅炉房司炉工人员安排工作 | C28: 天津恒盛嘉业科技有限公司 | D28: 2022.10.19 | E28: 700108 | G28: 100000 | H28: =E28-G28 -> 600108
A29: 22-HT-YY-028 | B29: 和平村锅炉房司炉工人员安排工作 | C29: 众投机电安装（天津）有限公司 | D29: 2022.10.19 | E29: 320492 | H29: =E29-G29 -> 320492
A30: 22-HT-YY-029 | B30: 万新村供热站、和平村供热站设备安全、正常运行服务协议 | C30: 河北工大科雅能源科技股份有限公司 | D30: 2022.11.25 | E30: 815100 | G30: =50000+100000 -> 150000 | H30: =E30-G30 -> 665100
A31: 22-HT-YY-030 | B31: 华腾、和平村供热站废气检测 | C31: 天津纳宝产品检测有限公司 | E31: 564440 | G31: =112888+112888+150000+188664 -> 564440 | H31: =E31-G31 -> 0
A32: 22-HT-YY-031 | B32: 华腾供热海河地热站、华馨地热站、嘉华地热站、中山门地热站、东康地热站压力表安全阀校准 | C32: 天津赛恩斯检测服务有限公司 | E32: 46534 | G32: 46534 | H32: =E32-G32 -> 0
A33: 22-HT-YY-032 | B33: 华腾万新村供热站下属换热站水泵维修项目 | C33: 天津市西青区万润机电设备维修中心 | E33: 46534 | G33: 46534 | H33: =E33-G33 -> 0 | I33: 无合同
A34: 22-HT-YY-033 | B34: 盛东北园锁闭阀更换 | C34: 天津鑫隆建筑工程有限公司 | E34: 52666 | G34: 52666 | H34: =E34-G34 -> 0
A35: 22-HT-YY-034 | B35: 负责品香苑、秀悦园、香兰、中山门、嘉华、东瑞、东惠、华馨、海河地热站维护值守和调试工作 | C35: 天津市津东创展城市发展有限公司 | D35: 2022.10.24 | E35: 648000 | G35: =144000+504000 -> 648000 | H35: =E35-G35 -> 0
A36: 22-HT-YY-035 | B36: 华腾供热站趸售改造工程——防爆电动调节阀采购项目 | C36: 天津凯世通阀门制造有限公司 | E36: 517150 | G36: =57150+150000+30000+80000+100000+100000 -> 517150 | H36: =E36-G36 -> 0
A37: 22-HT-YY-036 | B37: 华腾供热站趸售改造工程——板式换热器采购项目 | C37: 天津开发区大新工程技术有限公司 | D37: 2022.10.19 | E37: 1480000 | G37: =100000+150000 -> 250000 | H37: =E37-G37 -> 1230000
A38: 22-HT-YY-037 | B38: 作废 | I38: 乙方说合同作废
A39: 22-HT-YY-038 | B39: 作废 | I39: 乙方说合同作废
A40: 22-HT-YY-039 | B40: 华腾潜水泵维修及洗井项目 | C40: 天津天泰轩泓地热科技发展有限公司 | D40: 2022.5.18 | E40: 713008 | G40: =43008+150000+100000+150000+20000 -> 463008 | H40: =E40-G40 -> 250000
...

Sheet 华腾2023
A1: 序号 | B1: 工程地点及内容 | C1: 单位名称 | D1: 签订日期 | E1: 合同额 | F1: 结算值 | G1: 已付款 | H1: 欠付款 | I1: 备注
A2: 23-HT-YY-001 | B2: 万新村、和平村在线监测设备维护 | C2: 天津市天一生态环境科技有限公司 | D2: 2023.1.17 | E2: 154000 | G2: =92400+61600 -> 154000 | H2: =E2-G2 -> 0
A3: 23-HT-YY-002 | B3: 万新村供热站、和平村供热站锅炉保养 | C3: 天津市辰雨达机电设备销售有限公司 | D3: 2023.1.17 | E3: 187000 | G3: =74800+112200 -> 187000 | H3: =E3-G3 -> 0
A4: 23-HT-YY-003 | B4: 东康家园抢修 | C4: 天津天泰宏凯泵业制造有限公司 | D4: 2023.2.1 | E4: 118000 | G4: 118000 | H4: =E4-G4 -> 0
A5: 23-HT-YY-004 | B5: 2022年华腾供热冬季备品备件维修材料采购 | C5: 天津市重信瑞能科技发展有限公司 | D5: 2023.1.5 | E5: 994146 | G5: =100000+100000+180000+128000 -> 508000 | H5: =E5-G5 -> 486146
A6: 23-HT-YY-005 | B6: 万新村、和平村供热站采购 | C6: 天津市北方建华机电设备有限公司 | D6: 2023.2.11 | E6: 92771 | G6: 80000 | H6: =E6-G6 -> 12771 | I6: 开票时：将维修费和采购费用分开开票
A7: 23-HT-YY-006 | B7: 华腾供热趸热购板片 | C7: 天津市津能双鹤热力设备有限公司 | D7: 2023.1.30 | E7: 648000 | G7: =180000+468000 -> 648000 | H7: =E7-G7 -> 0
A8: 23-HT-YY-007 | B8: 华腾锅炉房升级改造项目 | C8: 天津市津能双鹤热力设备有限公司 | D8: 2023.4.24 | E8: 270000 | G8: =120000+100000+50000 -> 270000 | H8: =E8-G8 -> 0
A9: 23-HT-YY-008 | B9: 海河供热站自来水及一次管网改造工程 | C9: 天津市融辉政达建筑工程有限公司 | D9: 2023.2.16 | E9: 70500 | F9: 70500 | G9: =50000+20500 -> 70500 | H9: =E9-G9 -> 0
A10: 23-HT-YY-009 | B10: 华腾地热测绘服务 | C10: 天津恒德建设工程技术有限公司 | D10: 2023.2.21 | E10: 457600 | G10: =100000+20000+50000 -> 170000 | H10: =E10-G10 -> 287600
A11: 23-HT-YY-010 | B11: 华腾供热在线监测设备数采仪更换及在线设备分析仪维修 | C11: 天津市天一生态环境科技有限公司 | D11: 2023.2.21 | E11: 316000 | G11: =100000+50000+100000 -> 250000 | H11: =E11-G11 -> 66000 | I11: 开票时：将维修费和采购费用分开开票
A12: 23-HT-YY-011 | B12: 和平村供热站管道漏水检测 | C12: 久跃管道工程（天津）有限公司 | D12: 2023.2.10 | E12: 11157 | G12: 11157 | H12: =E12-G12 -> 0
A13: 23-HT-YY-012 | B13: 购臭味剂、工业盐（第一批） | C13: 廊坊一萍锅炉保养工程有限公司 | D13: 2023.1.9 | E13: 897650 | G13: 160000 | H13: =E13-G13 -> 737650
A14: 23-HT-YY-013 | B14: 缓蚀阻垢剂（第一批) | C14: 天津大展锅炉技术有限公司 | D14: 2023.1.9 | E14: 880000 | H14: =E14-G14 -> 880000
A15: 23-HT-YY-014 | B15: 购缓蚀色精、缓蚀阻垢剂（第一批) | C15: 廊坊诺一锅炉保养有限公司 | D15: 2023.1.9 | E15: 727000 | G15: =90000+170000 -> 260000 | H15: =E15-G15 -> 467000
A16: 23-HT-YY-015 | B16: 万新村供热系统评价及供热系统运行策略指导 | C16: 天津清捷能源环境科技有限公司 | D16: 2023.2.28 | E16: 650000 | G16: =195000+195000+150000+110000 -> 650000 | H16: =E16-G16 -> 0
A17: 23-HT-YY-016 | B17: 缓蚀阻垢剂（第二批) | C17: 天津大展锅炉技术有限公司 | D17: 2023.2.28 | E17: 880000 | H17: =E17-G17 -> 880000
A18: 23-HT-YY-017 | B18: 购臭味剂、缓蚀色精（第二批） | C18: 廊坊诺一锅炉保养有限公司 | D18: 2023.2.28 | E18: 875200 | H18: =E18-G18 -> 875200
A19: 23-HT-YY-018 | B19: 板换清洗镀膜保养施工 | C19: 天津大展锅炉技术有限公司 | D19: 2023.2.28 | E19: 386295.8 | H19: =E19-G19 -> 386295.8
A20: 23-HT-YY-019 | B20: 购板式换热器、胶垫 | C20: 天津开发区大新工程技术有限公司 | D20: 2023.2.27 | E20: 72104 | H20: =E20-G20 -> 72104
A21: 23-HT-YY-020 | B21: 板式换热器维修 | C21: 天津开发区大新工程技术有限公司 | D21: 2023.2.28 | E21: 136700 | G21: 136700 | H21: =E21-G21 -> 0
A22: 23-HT-YY-021 | B22: 华腾供热公司趸热隔压换热站改造工程 | C22: 天津市政工程设计研究总院有限公司 | D22: 2023.2.13 | E22: 192000 | G22: 50000 | H22: =E22-G22 -> 142000
A23: 23-HT-YY-022 | B23: 购缓蚀阻垢剂（第三批） | C23: 天津大展锅炉技术有限公司 | D23: 2023.3.6 | E23: 440000 | G23: =176000+150000 -> 326000 | H23: =E23-G23 -> 114000
A24: 23-HT-YY-023 | B24: 购臭味剂 | C24: 廊坊一萍锅炉保养工程有限公司 | D24: 2023.3.3 | E24: 403200 | H24: =E24-G24 -> 403200
A25: 23-HT-YY-024 | B25: 购臭味剂、工业盐（第二批） | C25: 廊坊一萍锅炉保养工程有限公司 | D25: 2023.2.27 | E25: 847250 | H25: =E25-G25 -> 847250
A26: 23-HT-YY-025 | B26: 华腾供热管道检测 | C26: 久跃管道工程（天津）有限公司 | D26: 2023.2.28 | E26: 36000 | G26: 36000 | H26: =E26-G26 -> 0
A27: 23-HT-YY-026 | B27: 购缓蚀色精（第三批） | C27: 廊坊诺一锅炉保养有限公司 | D27: 2023.3.1 | E27: 743600 | H27: =E27-G27 -> 743600
A28: 23-HT-YY-027 | B28: 万新村供热站板换清洗抢修 | C28: 天津大展建筑工程有限公司 | D28: 2023.1.18 | E28: 135460 | G28: 135460 | H28: =E28-G28 -> 0
A29: 23-HT-YY-028 | B29: 华腾供热地热供热站清洗抢修 | C29: 天津市昌青建筑工程有限公司 | D29: 2023.1.18 | E29: 170358 | G29: 170358 | H29: =E29-G29 -> 0
A30: 23-HT-YY-029 | B30: 华腾供热四号站换热器更换项目 | C30: 天津普达瑞克机电工程有限公司 | D30: 2023.3.13 | E30: 215892 | H30: =E30-G30 -> 215892
A31: 23-HT-YY-030 | B31: 2023年1月份维修材料采购 | C31: 天津普达瑞克机电工程有限公司 | D31: 2023.4.3 | E31: 402106 | H31: =E31-G31 -> 402106
A32: 23-HT-YY-031 | B32: 香邑国际18号楼门前、远洋食堂外人行便道给定范围内物探 | C32: 天津海滨工程勘察设计有限公司 | D32: 2023.4.3 | E32: 15800 | G32: 15800 | H32: =E32-G32 -> 0
A33: 23-HT-YY-032 | B33: 2023年造价咨询合同框架协议 | C33: 天津宸颍工程咨询有限公司 | D33: 2023.2.10 | E33: 框架协议 | F33: =120082-1700+21452 -> 139834 | G33: =29411+51467 -> 80878 | H33: =F33-G33 -> 58956
A34: 23-HT-YY-033 | B34: 华腾供热站内燃气管道维护 | C34: 程然（天津）建设集团有限公司 | D34: 2023.4.19 | E34: 195000 | G34: =30000+165000 -> 195000 | H34: =E34-G34 -> 0
A35: 23-HT-YY-034 | B35: 华腾供热4号站蝶式止回阀采购项目 | C35: 天津市塘沽塘阀阀门有限公司 | D35: 2023.3.22 | E35: 5730 | G35: 5730 | H35: =E35-G35 -> 0
A36: 23-HT-YY-035 | B36: 孵化园咨询服务 | C36: 天津清捷能源环境科技有限公司 | D36: 2023.4.20 | E36: 50000 | G36: 20000 | H36: =E36-G36 -> 30000
A37: 23-HT-YY-036 | B37: 2023年度华腾供热招标代理服务 | C37: 天津市泛亚工程咨询有限公司 | D37: 2023.4.7 | E37: 无明细 | H37: 无明细
A38: 23-HT-YY-037 | B38: 2023年度华腾供热招标代理服务 | C38: 天津宸颖工程咨询有限公司 | D38: 2023.4.7 | E38: 无明细 | H38: 无明细
A39: 23-HT-YY-038 | B39: 2023年度华腾供热招标代理服务 | C39: 天津津运工程咨询有限公司 | D39: 2023.4.7 | E39: 无明细 | H39: 无明细
A40: 23-HT-YY-039 | B40: 2023年度华腾供热招标代理服务 | C40: 中大国信工程管理有限公司 | D40: 2023.5.25 | E40: 无明细 | H40: 无明细
...

Sheet 华腾2021-2023汇总
A1: 华腾供热2021-2023年工程欠款明细表
A2: 序号 | B2: 工程地点及内容 | C2: 单位名称 | D2: 合同额 | E2: 结算值 | F2: 已付款 | G2: 欠付款 | H2: 备注
A3: 2021 | B3: 三东小区冬季抢修 | C3: 天津天铖力帆建筑工程有限公司 | D3: =华腾2021!E2 -> 25864 | E3: =华腾2021!F2 -> 25864 | F3: =华腾2021!G2 -> 25864 | G3: =E3-F3 -> 0
A4: 2021 | B4: 和平村站内检修 | C4: 天津永强东成市政工程有限公司 | D4: =华腾2021!E3 -> 87020 | E4: =华腾2021!F3 -> 87020 | F4: =华腾2021!G3 -> 87020 | G4: =E4-F4 -> 0
A5: 2021 | B5: 东城家园冬季检修 | C5: 天津永强东成市政工程有限公司 | D5: =华腾2021!E4 -> 46176 | E5: =华腾2021!F4 -> 46176 | F5: =华腾2021!G4 -> 46176 | G5: =E5-F5 -> 0
A6: 2021 | B6: 冬季内网抢修 | C6: 禹王（北京）科技工程有限公司 | D6: =华腾2021!E5 -> 255735 | E6: =华腾2021!F5 -> 255735 | F6: =华腾2021!G5 -> 255735 | G6: =E6-F6 -> 0
A7: 2021 | B7: 百合春天 九号站冬季抢修 | C7: 天津恒鼎建筑工程有限公司 | D7: =华腾2021!E6 -> 361256 | E7: =华腾2021!F6 -> 361256 | F7: =华腾2021!G6 -> 361256 | G7: =E7-F7 -> 0
A8: 2021 | B8: 万新供热2020-2021冬季运行供热管网抢修 | C8: 河北省广平县建筑安装企业集团公司 | D8: =华腾2021!E7 -> 136139 | E8: =华腾2021!F7 -> 136139 | F8: =华腾2021!G7 -> 136139 | G8: =E8-F8 -> 0
A9: 2021 | B9: 海河华馨冬季抢修 | C9: 天津市信恒建筑工程有限公司 | D9: =华腾2021!E8 -> 196770 | E9: =华腾2021!F8 -> 196770 | F9: =华腾2021!G8 -> 196770 | G9: =E9-F9 -> 0
A10: 2021 | B10: 团结北里秋丽家园冬季抢修 | C10: 天津军星管业集团建设工程有限公司 | D10: =华腾2021!E9 -> 29070 | E10: =华腾2021!F9 -> 29070 | F10: =华腾2021!G9 -> 29070 | G10: =E10-F10 -> 0
A11: 2021 | B11: 嘉华翠海朱庄子一村冬季抢修 | C11: 隽融建工（集团）有限公司 | D11: =华腾2021!E10 -> 90133 | E11: =华腾2021!F10 -> 90133 | F11: =华腾2021!G10 -> 90133 | G11: =E11-F11 -> 0
A12: 2021 | B12: 6号站万新公寓冬季抢修 | C12: 天津市翔凯建筑安装工程有限公司 | D12: =华腾2021!E11 -> 55095 | E12: =华腾2021!F11 -> 55095 | F12: =华腾2021!G11 -> 55095 | G12: =E12-F12 -> 0
A13: 2021 | B13: 2021年万新村1#2#3#换热站屋顶修缮工程 | C13: 天津大鼎市政工程有限公司 | D13: =华腾2021!E12 -> 179970 | E13: =华腾2021!F12 -> 172346 | F13: =华腾2021!G12 -> 172346 | G13: =E13-F13 -> 0 | H13: 郭天刚 18649222399
A14: 2021 | B14: 2021年万新村7#8#9#换热站屋顶修缮工程 | C14: 天津大鼎市政工程有限公司 | D14: =华腾2021!E13 -> 167424 | E14: =华腾2021!F13 -> 160232 | F14: =华腾2021!G13 -> 160232 | G14: =E14-F14 -> 0 | H14: 郭天刚 18649222399
A15: 2021 | B15: 2021年倚虹里1#-5#楼管道保温修缮工程 | C15: 天津大鼎市政工程有限公司 | D15: =华腾2021!E14 -> 163218 | E15: =华腾2021!F14 -> 161004 | F15: =华腾2021!G14 -> 161004 | G15: =E15-F15 -> 0 | H15: 郭天刚 18649222399
A16: 2021 | B16: 2021年松风西里1#-6#楼管道保温修缮工程 | C16: 天津大鼎市政工程有限公司 | D16: =华腾2021!E15 -> 184255 | E16: =华腾2021!F15 -> 177994 | F16: =华腾2021!G15 -> 177994 | G16: =E16-F16 -> 0 | H16: 郭天刚 18649222399
A17: 2021 | B17: 2021年一村换热站屋顶修缮工程 | C17: 天津大鼎市政工程有限公司 | D17: =华腾2021!E16 -> 161021 | E17: =华腾2021!F16 -> 153831 | F17: =华腾2021!G16 -> 153831 | G17: =E17-F17 -> 0 | H17: 郭天刚 18649222399
A18: 2021 | B18: 2021年和平村锅炉房手动葫芦改造工程 | C18: 天津大鼎市政工程有限公司 | D18: =华腾2021!E17 -> 124818 | E18: =华腾2021!F17 -> 115036 | F18: =华腾2021!G17 -> 115036 | G18: =E18-F18 -> 0 | H18: 郭天刚 18649222399
A19: 2021 | B19: 2021年倚虹中里1#-8#楼管道保温修缮工程 | C19: 天津大鼎市政工程有限公司 | D19: =华腾2021!E18 -> 173010 | E19: =华腾2021!F18 -> 169972 | F19: =华腾2021!G18 -> 169972 | G19: =E19-F19 -> 0 | H19: 郭天刚 18649222399
A20: 2021 | B20: 2021年倚虹东里1#-5#楼管道保温修缮工程 | C20: 天津大鼎市政工程有限公司 | D20: =华腾2021!E19 -> 159886 | E20: =华腾2021!F19 -> 158558 | F20: =华腾2021!G19 -> 158558 | G20: =E20-F20 -> 0 | H20: 郭天刚 18649222399
A21: 2021 | B21: 2021年万新村锅炉手动葫芦改造工程 | C21: 天津大鼎市政工程有限公司 | D21: =华腾2021!E20 -> 110949 | E21: =华腾2021!F20 -> 102255 | F21: =华腾2021!G20 -> 102255 | G21: =E21-F21 -> 0 | H21: 郭天刚 18649222399
A22: 2021 | B22: 2021年松风东里1#-5#楼管道保温修缮工程 | C22: 天津大鼎市政工程有限公司 | D22: =华腾2021!E21 -> 167423 | E22: =华腾2021!F21 -> 160729 | F22: =华腾2021!G21 -> 160729 | G22: =E22-F22 -> 0 | H22: 郭天刚 18649222399
A23: 2021 | B23: 2021年香兰家园换热站屋顶修缮工程 | C23: 天津大鼎市政工程有限公司 | D23: =华腾2021!E22 -> 174126 | E23: =华腾2021!F22 -> 166648 | F23: =华腾2021!G22 -> 166648 | G23: =E23-F23 -> 0 | H23: 郭天刚 18649222399
A24: 2021 | B24: 2021年百合春天换热站屋顶修缮工程 | C24: 天津大鼎市政工程有限公司 | D24: =华腾2021!E23 -> 182801 | E24: =华腾2021!F23 -> 175177 | F24: =华腾2021!G23 -> 175177 | G24: =E24-F24 -> 0 | H24: 郭天刚 18649222399
... A30: 2021 | B30: 2021年天泉东里3#4#入口截门更换工程 | C30: 中舰建筑工程（天津）有限公司 | D30: =华腾2021!E29 -> 151117 | E30: =华腾2021!F29 -> 141768 | F30: =华腾2021!G29 -> 141768 | G30: =E30-F30 -> 0 | H30: 郭天刚 18649222399
A31: 2021 | B31: 2021年秀悦换热站变压器维修项目 | C31: 中舰建筑工程（天津）有限公司 | D31: =华腾2021!E30 -> 188800 | E31: =华腾2021!F30 -> 0 | F31: =华腾2021!G30 -> 188800 | G31: =D31-F31 -> 0 | H31: 郭天刚 18649222399
A32: 2021 | B32: 2021年天泉西里14#15#16#17#入口截门更换工程 | C32: 中舰建筑工程（天津）有限公司 | D32: =华腾2021!E31 -> 181657 | E32: =华腾2021!F31 -> 169831 | F32: =华腾2021!G31 -> 169831 | G32: =E32-F32 -> 0 | H32: 郭天刚 18649222399
A33: 2021 | B33: 2021年远翠东里15#-23#入口截门更换工程 | C33: 中舰建筑工程（天津）有限公司 | D33: =华腾2021!E32 -> 190750 | E33: =华腾2021!F32 -> 177941 | F33: =华腾2021!G32 -> 177941 | G33: =E33-F33 -> 0 | H33: 郭天刚 18649222399
A34: 2021 | B34: 2021年和平村供热站变压器维修项目 | C34: 中舰建筑工程（天津）有限公司 | D34: =华腾2021!E33 -> 152701 | E34: =华腾2021!F33 -> 0 | F34: =华腾2021!G33 -> 152701 | G34: =D34-F34 -> 0 | H34: 郭天刚 18649222399
A35: 2021 | B35: 2021年贵环换热站变压器维修项目 | C35: 中舰建筑工程（天津）有限公司 | D35: =华腾2021!E34 -> 133848 | E35: =华腾2021!F34 -> 0 | F35: =华腾2021!G34 -> 133848 | G35: =D35-F35 -> 0 | H35: 郭天刚 18649222399
A36: 2021 | B36: 2021年香兰嘉园换热站变压器维修项目 | C36: 中舰建筑工程（天津）有限公司 | D36: =华腾2021!E35 -> 136749 | E36: =华腾2021!F35 -> 0 | F36: =华腾2021!G35 -> 136749 | G36: =D36-F36 -> 0 | H36: 郭天刚 18649222399
A37: 2021 | B37: 2021华馨地热站变压器维修项目 | C37: 中舰建筑工程（天津）有限公司 | D37: =华腾2021!E36 -> 192817 | E37: =华腾2021!F36 -> 0 | F37: =华腾2021!G36 -> 192817 | G37: =D37-F37 -> 0 | H37: 郭天刚 18649222399
A38: 2021 | B38: 2021年东城家园及和平村夏季检修工程 | C38: 天津永强东成市政工程有限公司 | D38: =华腾2021!E37 -> 170458 | E38: =华腾2021!F37 -> 170458 | F38: =华腾2021!G37 -> 170458 | G38: =D38-F38 -> 0
A39: 2021 | B39: 华腾招标代理咨询费/华腾供热站入围项目邀请招标 | C39: 天津津建工程造价咨询有限公司 | D39: =华腾2021!E38 -> 1291000 | E39: =华腾2021!F38 -> 0 | F39: =华腾2021!G38 -> 694000 | G39: =D39-F39 -> 597000
A40: 2021 | B40: 华腾供热有限责任公司各换热站变速器检测校准项目 | C40: 天津天星科技发展有限公司 | D40: =华腾2021!E39 -> 194400 | E40: =华腾2021!F39 -> 0 | F40: =华腾2021!G39 -> 194400 | G40: =D40-F40 -> 0 | H40: 郭天刚 18649222399
A41: 2021 | B41: 华腾供热有限责任公司流量计维护保养项目 | C41: 中舰建筑工程（天津）有限公司 | D41: =华腾2021!E40 -> 198856 | E41: =华腾2021!F40 -> 0 | F41: =华腾2021!G40 -> 198856 | G41: =D41-F41 -> 0 | H41: 郭天刚 18649222399
A42: 2021 | B42: 华腾供热贵环站站内夏季零星检修工程 | C42: 河北省广平县建筑安装企业集团公司 | D42: =华腾2021!E41 -> 197813 | E42: =华腾2021!F41 -> 0 | F42: =华腾2021!G41 -> 47813 | G42: =D42-F42 -> 150000
A43: 2021 | B43: 华腾供热临月里夏季零星检修工程 | C43: 河北省广平县建筑安装企业集团公司 | D43: =华腾2021!E42 -> 199772 | E43: =华腾2021!F42 -> 0 | F43: =华腾2021!G42 -> 99772 | G43: =D43-F43 -> 100000
A44: 2021 | B44: 华腾供热昆仑里、昆华里、昆悦里夏季零星检修工程 | C44: 天津荣开建筑工程有限公司 | D44: =华腾2021!E43 -> 191849 | E44: =华腾2021!F43 -> 0 | F44: =华腾2021!G43 -> 41849 | G44: =D44-F44 -> 150000
A45: 2021 | B45: 华腾供热晟悦、品香、润风、润景外网漏水检修工程 | C45: 天津荣开建筑工程有限公司 | D45: =华腾2021!E44 -> 97929 | E45: =华腾2021!F44 -> 0 | F45: =华腾2021!G44 -> 97929 | G45: =D45-F45 -> 0
...
